{
 "cells": [
  {
   "cell_type": "code",
   "execution_count": null,
   "metadata": {},
   "outputs": [],
   "source": []
  },
  {
   "cell_type": "code",
   "execution_count": 2,
   "metadata": {},
   "outputs": [],
   "source": [
    "import os\n",
    "\n",
    "# get from https://platform.openai.com/\n",
    "os.environ[\"OPENAI_API_KEY\"] = os.environ.get(\"OPENAI_API_KEY\", \"\")\n",
    "\n",
    "# get from https://nla.zapier.com/docs/authentication/ after logging in):\n",
    "os.environ[\"ZAPIER_NLA_API_KEY\"] = os.environ.get(\"ZAPIER_NLA_API_KEY\", \"\")"
   ]
  },
  {
   "cell_type": "code",
   "execution_count": 3,
   "metadata": {},
   "outputs": [],
   "source": [
    "from langchain.agents import AgentType, initialize_agent\n",
    "from langchain_community.agent_toolkits import ZapierToolkit\n",
    "from langchain_community.utilities.zapier import ZapierNLAWrapper\n",
    "from langchain_openai import OpenAI"
   ]
  },
  {
   "cell_type": "code",
   "execution_count": 4,
   "metadata": {},
   "outputs": [
    {
     "ename": "ValidationError",
     "evalue": "1 validation error for ZapierNLAWrapper\n  Value error, Did not find zapier_nla_api_key, please add an environment variable `ZAPIER_NLA_API_KEY` which contains it, or pass `zapier_nla_api_key` as a named parameter. [type=value_error, input_value={'zapier_nla_oauth_access_token': ''}, input_type=dict]\n    For further information visit https://errors.pydantic.dev/2.10/v/value_error",
     "output_type": "error",
     "traceback": [
      "\u001b[1;31m---------------------------------------------------------------------------\u001b[0m",
      "\u001b[1;31mValidationError\u001b[0m                           Traceback (most recent call last)",
      "Cell \u001b[1;32mIn[4], line 2\u001b[0m\n\u001b[0;32m      1\u001b[0m llm \u001b[38;5;241m=\u001b[39m OpenAI(temperature\u001b[38;5;241m=\u001b[39m\u001b[38;5;241m0\u001b[39m)\n\u001b[1;32m----> 2\u001b[0m zapier \u001b[38;5;241m=\u001b[39m ZapierNLAWrapper()\n\u001b[0;32m      3\u001b[0m toolkit \u001b[38;5;241m=\u001b[39m ZapierToolkit\u001b[38;5;241m.\u001b[39mfrom_zapier_nla_wrapper(zapier)\n\u001b[0;32m      4\u001b[0m agent \u001b[38;5;241m=\u001b[39m initialize_agent(\n\u001b[0;32m      5\u001b[0m     toolkit\u001b[38;5;241m.\u001b[39mget_tools(), llm, agent\u001b[38;5;241m=\u001b[39mAgentType\u001b[38;5;241m.\u001b[39mZERO_SHOT_REACT_DESCRIPTION, verbose\u001b[38;5;241m=\u001b[39m\u001b[38;5;28;01mTrue\u001b[39;00m\n\u001b[0;32m      6\u001b[0m )\n",
      "File \u001b[1;32mc:\\Users\\Zabih\\anaconda3\\Lib\\site-packages\\pydantic\\main.py:214\u001b[0m, in \u001b[0;36mBaseModel.__init__\u001b[1;34m(self, **data)\u001b[0m\n\u001b[0;32m    212\u001b[0m \u001b[38;5;66;03m# `__tracebackhide__` tells pytest and some other tools to omit this function from tracebacks\u001b[39;00m\n\u001b[0;32m    213\u001b[0m __tracebackhide__ \u001b[38;5;241m=\u001b[39m \u001b[38;5;28;01mTrue\u001b[39;00m\n\u001b[1;32m--> 214\u001b[0m validated_self \u001b[38;5;241m=\u001b[39m \u001b[38;5;28mself\u001b[39m\u001b[38;5;241m.\u001b[39m__pydantic_validator__\u001b[38;5;241m.\u001b[39mvalidate_python(data, self_instance\u001b[38;5;241m=\u001b[39m\u001b[38;5;28mself\u001b[39m)\n\u001b[0;32m    215\u001b[0m \u001b[38;5;28;01mif\u001b[39;00m \u001b[38;5;28mself\u001b[39m \u001b[38;5;129;01mis\u001b[39;00m \u001b[38;5;129;01mnot\u001b[39;00m validated_self:\n\u001b[0;32m    216\u001b[0m     warnings\u001b[38;5;241m.\u001b[39mwarn(\n\u001b[0;32m    217\u001b[0m         \u001b[38;5;124m'\u001b[39m\u001b[38;5;124mA custom validator is returning a value other than `self`.\u001b[39m\u001b[38;5;130;01m\\n\u001b[39;00m\u001b[38;5;124m'\u001b[39m\n\u001b[0;32m    218\u001b[0m         \u001b[38;5;124m\"\u001b[39m\u001b[38;5;124mReturning anything other than `self` from a top level model validator isn\u001b[39m\u001b[38;5;124m'\u001b[39m\u001b[38;5;124mt supported when validating via `__init__`.\u001b[39m\u001b[38;5;130;01m\\n\u001b[39;00m\u001b[38;5;124m\"\u001b[39m\n\u001b[0;32m    219\u001b[0m         \u001b[38;5;124m'\u001b[39m\u001b[38;5;124mSee the `model_validator` docs (https://docs.pydantic.dev/latest/concepts/validators/#model-validators) for more details.\u001b[39m\u001b[38;5;124m'\u001b[39m,\n\u001b[0;32m    220\u001b[0m         stacklevel\u001b[38;5;241m=\u001b[39m\u001b[38;5;241m2\u001b[39m,\n\u001b[0;32m    221\u001b[0m     )\n",
      "\u001b[1;31mValidationError\u001b[0m: 1 validation error for ZapierNLAWrapper\n  Value error, Did not find zapier_nla_api_key, please add an environment variable `ZAPIER_NLA_API_KEY` which contains it, or pass `zapier_nla_api_key` as a named parameter. [type=value_error, input_value={'zapier_nla_oauth_access_token': ''}, input_type=dict]\n    For further information visit https://errors.pydantic.dev/2.10/v/value_error"
     ]
    }
   ],
   "source": [
    "llm = OpenAI(temperature=0)\n",
    "zapier = ZapierNLAWrapper()\n",
    "toolkit = ZapierToolkit.from_zapier_nla_wrapper(zapier)\n",
    "agent = initialize_agent(\n",
    "    toolkit.get_tools(), llm, agent=AgentType.ZERO_SHOT_REACT_DESCRIPTION, verbose=True\n",
    ")"
   ]
  }
 ],
 "metadata": {
  "kernelspec": {
   "display_name": "base",
   "language": "python",
   "name": "python3"
  },
  "language_info": {
   "codemirror_mode": {
    "name": "ipython",
    "version": 3
   },
   "file_extension": ".py",
   "mimetype": "text/x-python",
   "name": "python",
   "nbconvert_exporter": "python",
   "pygments_lexer": "ipython3",
   "version": "3.12.7"
  }
 },
 "nbformat": 4,
 "nbformat_minor": 2
}
